Workbook

Sheet NFR3 Version 1
A1: NFR3 · Lesson-plan accuracy (Test 6) — Lesson planner v1
A2: This checks whether the transcript analysis finds what is really in a transcript, and only that.
A3: Method
A4: 1. Reproduction carried out on 21 October 2026, because the original per-feature records were not retained. Same 60 transcripts (T01–T60) and the same frozen truth sheets as the v3 run (SHA-256 verified); each transcript run once, in order T01→T60, with nothing else on the GPU.
A5: 2. Lesson planner v1 (lesson_planner.py, unchanged): qwen2.5:3b via Ollama, model defaults (the file sets no seed or temperature). Run on the labelled transcripts ("Therapist." / "Child." kept), as the original v1 run was. T11–T60 are new for v1 (originally only T01–T10 were run).
A6: 3. 181 planted features: T01–T20 from features.json (story parts left out, use of 'because'/'so', emotion words); T21–T60 from the T21–T30 and T31–T60 truth sheets, scored by meaning (parts left out, feelings, reasons).
A7: 4. v1 writes free text, which the v3 scorer (compare.py) cannot read, so each plan was scored by reading it against the same truth sheets with the same fixed rules: sections 1–4 only; a planted feature reported = hit, not reported = miss; a gap reported in a planted category that is not real = false alarm (one row each). Judgement calls carry a comment and are listed in needs_manual_check.md.
A8: 5. Every string the plan quotes as said in the session (sections 1–5; the Suggested Reachy Prompts are excluded) was checked against the labelled transcript and marked exact (word for word, ignoring case and punctuation), reworded (same meaning) or not there (not said, or meaning changed). Non-exact marks are provisional (cell comments) until checked by hand (needs_manual_check.md); proposed questions and suggestions not offered as the child's words are left out.
A9: Raw plans: evaluation/rerun_2026-10-21/v1/. Run log, hashes and model digests: run_log.md.
A11: Results | G11: Set | H11: hits | I11: planted | J11: hit rate | K11: false alarms | L11: false alarms per transcript | M11: quotes checked | N11: quotes not there
A12: Hit rate (hits ÷ planted features) | C12: =IF(COUNTIF($C$17:$C$258,"Y")=0,"",COUNTIF($E$17:$E$258,"hit")/COUNTIF($C$17:$C$258,"Y")) | G12: T01–T10 | H12: =COUNTIFS($A$17:$A$258,">=T01",$A$17:$A$258,"<=T10",$E$17:$E$258,"hit") | I12: =COUNTIFS($A$17:$A$258,">=T01",$A$17:$A$258,"<=T10",$C$17:$C$258,"Y") | J12: =IF(I12=0,"",H12/I12) | K12: =COUNTIFS($A$17:$A$258,">=T01",$A$17:$A$258,"<=T10",$E$17:$E$258,"false alarm") | L12: =K12/10 | M12: =COUNTIFS($A$267:$A$766,">=T01",$A$267:$A$766,"<=T10") | N12: =COUNTIFS($A$267:$A$766,">=T01",$A$267:$A$766,"<=T10",$C$267:$C$766,"not there")
A13: False alarms per transcript | C13: {=IF(SUMPRODUCT(($A$17:$A$258<>"")/COUNTIF($A$17:$A$258,$A$17:$A$258&""))=0,"",COUNTIF($E$17:$E$258,"false alarm")/SUMPRODUCT(($A$17:$A$258<>"")/COUNTIF($A$17:$A$258,$A$17:$A$258&"")))} | G13: T11–T20 | H13: =COUNTIFS($A$17:$A$258,">=T11",$A$17:$A$258,"<=T20",$E$17:$E$258,"hit") | I13: =COUNTIFS($A$17:$A$258,">=T11",$A$17:$A$258,"<=T20",$C$17:$C$258,"Y") | J13: =IF(I13=0,"",H13/I13) | K13: =COUNTIFS($A$17:$A$258,">=T11",$A$17:$A$258,"<=T20",$E$17:$E$258,"false alarm") | L13: =K13/10 | M13: =COUNTIFS($A$267:$A$766,">=T11",$A$267:$A$766,"<=T20") | N13: =COUNTIFS($A$267:$A$766,">=T11",$A$267:$A$766,"<=T20",$C$267:$C$766,"not there")
A14: Quotes not in transcript | C14: =IF(COUNTA($C$267:$C$766)=0,"",COUNTIF($C$267:$C$766,"not there")/COUNTA($C$267:$C$766)) | G14: T21–T30 | H14: =COUNTIFS($A$17:$A$258,">=T21",$A$17:$A$258,"<=T30",$E$17:$E$258,"hit") | I14: =COUNTIFS($A$17:$A$258,">=T21",$A$17:$A$258,"<=T30",$C$17:$C$258,"Y") | J14: =IF(I14=0,"",H14/I14) | K14: =COUNTIFS($A$17:$A$258,">=T21",$A$17:$A$258,"<=T30",$E$17:$E$258,"false alarm") | L14: =K14/10 | M14: =COUNTIFS($A$267:$A$766,">=T21",$A$267:$A$766,"<=T30") | N14: =COUNTIFS($A$267:$A$766,">=T21",$A$267:$A$766,"<=T30",$C$267:$C$766,"not there")
A15: Precision (hits ÷ (hits + false alarms)) | C15: =IF(COUNTIF($E$17:$E$258,"hit")+COUNTIF($E$17:$E$258,"false alarm")=0,"",COUNTIF($E$17:$E$258,"hit")/(COUNTIF($E$17:$E$258,"hit")+COUNTIF($E$17:$E$258,"false alarm"))) | G15: T31–T60 | H15: =COUNTIFS($A$17:$A$258,">=T31",$A$17:$A$258,"<=T60",$E$17:$E$258,"hit") | I15: =COUNTIFS($A$17:$A$258,">=T31",$A$17:$A$258,"<=T60",$C$17:$C$258,"Y") | J15: =IF(I15=0,"",H15/I15) | K15: =COUNTIFS($A$17:$A$258,">=T31",$A$17:$A$258,"<=T60",$E$17:$E$258,"false alarm") | L15: =K15/30 | M15: =COUNTIFS($A$267:$A$766,">=T31",$A$267:$A$766,"<=T60") | N15: =COUNTIFS($A$267:$A$766,">=T31",$A$267:$A$766,"<=T60",$C$267:$C$766,"not there")
A16: transcript_id | B16: feature | C16: planted (Y/N) | D16: reported (Y/N) | E16: result (hit/miss/false alarm) | G16: All 60 | H16: =COUNTIFS($A$17:$A$258,">=T01",$A$17:$A$258,"<=T60",$E$17:$E$258,"hit") | I16: =COUNTIFS($A$17:$A$258,">=T01",$A$17:$A$258,"<=T60",$C$17:$C$258,"Y") | J16: =IF(I16=0,"",H16/I16) | K16: =COUNTIFS($A$17:$A$258,">=T01",$A$17:$A$258,"<=T60",$E$17:$E$258,"false alarm") | L16: =K16/60 | M16: =COUNTIFS($A$267:$A$766,">=T01",$A$267:$A$766,"<=T60") | N16: =COUNTIFS($A$267:$A$766,">=T01",$A$267:$A$766,"<=T60",$C$267:$C$766,"not there")
A17: T01 | B17: Leaves out: where | C17: Y | D17: Y | E17: hit
A18: T01 | B18: Uses 'because' | C18: Y | D18: Y | E18: hit
A19: T01 | B19: Emotion word: scared | C19: Y | D19: Y | E19: hit
A20: T01 | B20: Emotion word: happy | C20: Y | D20: Y | E20: hit
A21: T01 | B21: False alarm: what happened | C21: N | D21: Y | E21: false alarm
A22: T02 | B22: Leaves out: how it ended | C22: Y | D22: N | E22: miss
A23: T02 | B23: Uses neither 'because' nor 'so' | C23: Y | D23: N | E23: miss
A24: T02 | B24: Emotion word: excited | C24: Y | D24: Y | E24: hit
A25: T02 | B25: False alarm: who | C25: N | D25: Y | E25: false alarm
A26: T03 | B26: Leaves out: who | C26: Y | D26: Y | E26: hit
A27: T03 | B27: Uses 'so' | C27: Y | D27: Y | E27: hit
A28: T03 | B28: Emotion word: sad | C28: Y | D28: Y | E28: hit
... A231: T60 | B231: Gives a reason | C231: Y | D231: Y | E231: hit
A265: Quotes: every example the analysis quotes as said in the session, checked against the transcript
A266: transcript_id | B266: quote | C266: found (exact/reworded/not there)
A267: T01 | B267: scared | C267: exact
A268: T01 | B268: happy | C268: exact
A269: T01 | B269: I don't know | C269: exact
A270: T01 | B270: scared | C270: exact
A271: T01 | B271: got a sticker | C271: exact
A272: T02 | B272: lots of people from your class | C272: exact
A273: T02 | B273: excited | C273: exact
A274: T04 | B274: they were too hot | C274: exact
A275: T04 | B275: Mum came to get me | C275: reworded
A276: T05 | B276: The Tigers, | C276: exact
...

Sheet NFR3 Version 2
A1: NFR3 · Lesson-plan accuracy (Test 6) — Lesson planner v2
A2: This checks whether the transcript analysis finds what is really in a transcript, and only that.
A3: Method
A4: 1. Reproduction carried out on 21 October 2026, because the original per-feature records were not retained. Same 60 transcripts (T01–T60) and the same frozen truth sheets as the v3 run (SHA-256 verified); each transcript run once, in order T01→T60, with nothing else on the GPU.
A5: 2. Lesson planner v2 (lesson_planner_v2.py, unchanged): qwen3:8b via Ollama, thinking off, temperature 0 for checks and 0.2 for writing, seed 0. Speaker labels were removed and re-added automatically by v2, exactly as in the v3 run.
A6: 3. 181 planted features: T01–T20 from features.json (story parts left out, use of 'because'/'so', emotion words); T21–T60 from the T21–T30 and T31–T60 truth sheets, scored by meaning (parts left out, feelings, reasons).
A7: 4. Scored automatically with the same scorer as v3 (compare.py's rules, unchanged), from each plan's saved analysis: sections 2–4; a planted feature reported = hit, not reported = miss; a gap reported in a planted category that is not real = false alarm (one row each).
A8: 5. Every string the plan quotes as said in the session (sections 1–5; the Suggested Reachy Prompts are excluded) was checked against the labelled transcript and marked exact (word for word, ignoring case and punctuation), reworded (same meaning) or not there (not said, or meaning changed). Non-exact marks are provisional (cell comments) until checked by hand (needs_manual_check.md); proposed questions and suggestions not offered as the child's words are left out.
A9: Raw plans and analysis JSON: evaluation/rerun_2026-10-21/v2/. Run log, hashes and model digests: run_log.md.
A11: Results | G11: Set | H11: hits | I11: planted | J11: hit rate | K11: false alarms | L11: false alarms per transcript | M11: quotes checked | N11: quotes not there
A12: Hit rate (hits ÷ planted features) | C12: =IF(COUNTIF($C$17:$C$258,"Y")=0,"",COUNTIF($E$17:$E$258,"hit")/COUNTIF($C$17:$C$258,"Y")) | G12: T01–T10 | H12: =COUNTIFS($A$17:$A$258,">=T01",$A$17:$A$258,"<=T10",$E$17:$E$258,"hit") | I12: =COUNTIFS($A$17:$A$258,">=T01",$A$17:$A$258,"<=T10",$C$17:$C$258,"Y") | J12: =IF(I12=0,"",H12/I12) | K12: =COUNTIFS($A$17:$A$258,">=T01",$A$17:$A$258,"<=T10",$E$17:$E$258,"false alarm") | L12: =K12/10 | M12: =COUNTIFS($A$267:$A$766,">=T01",$A$267:$A$766,"<=T10") | N12: =COUNTIFS($A$267:$A$766,">=T01",$A$267:$A$766,"<=T10",$C$267:$C$766,"not there")
A13: False alarms per transcript | C13: {=IF(SUMPRODUCT(($A$17:$A$258<>"")/COUNTIF($A$17:$A$258,$A$17:$A$258&""))=0,"",COUNTIF($E$17:$E$258,"false alarm")/SUMPRODUCT(($A$17:$A$258<>"")/COUNTIF($A$17:$A$258,$A$17:$A$258&"")))} | G13: T11–T20 | H13: =COUNTIFS($A$17:$A$258,">=T11",$A$17:$A$258,"<=T20",$E$17:$E$258,"hit") | I13: =COUNTIFS($A$17:$A$258,">=T11",$A$17:$A$258,"<=T20",$C$17:$C$258,"Y") | J13: =IF(I13=0,"",H13/I13) | K13: =COUNTIFS($A$17:$A$258,">=T11",$A$17:$A$258,"<=T20",$E$17:$E$258,"false alarm") | L13: =K13/10 | M13: =COUNTIFS($A$267:$A$766,">=T11",$A$267:$A$766,"<=T20") | N13: =COUNTIFS($A$267:$A$766,">=T11",$A$267:$A$766,"<=T20",$C$267:$C$766,"not there")
A14: Quotes not in transcript | C14: =IF(COUNTA($C$267:$C$766)=0,"",COUNTIF($C$267:$C$766,"not there")/COUNTA($C$267:$C$766)) | G14: T21–T30 | H14: =COUNTIFS($A$17:$A$258,">=T21",$A$17:$A$258,"<=T30",$E$17:$E$258,"hit") | I14: =COUNTIFS($A$17:$A$258,">=T21",$A$17:$A$258,"<=T30",$C$17:$C$258,"Y") | J14: =IF(I14=0,"",H14/I14) | K14: =COUNTIFS($A$17:$A$258,">=T21",$A$17:$A$258,"<=T30",$E$17:$E$258,"false alarm") | L14: =K14/10 | M14: =COUNTIFS($A$267:$A$766,">=T21",$A$267:$A$766,"<=T30") | N14: =COUNTIFS($A$267:$A$766,">=T21",$A$267:$A$766,"<=T30",$C$267:$C$766,"not there")
A15: Precision (hits ÷ (hits + false alarms)) | C15: =IF(COUNTIF($E$17:$E$258,"hit")+COUNTIF($E$17:$E$258,"false alarm")=0,"",COUNTIF($E$17:$E$258,"hit")/(COUNTIF($E$17:$E$258,"hit")+COUNTIF($E$17:$E$258,"false alarm"))) | G15: T31–T60 | H15: =COUNTIFS($A$17:$A$258,">=T31",$A$17:$A$258,"<=T60",$E$17:$E$258,"hit") | I15: =COUNTIFS($A$17:$A$258,">=T31",$A$17:$A$258,"<=T60",$C$17:$C$258,"Y") | J15: =IF(I15=0,"",H15/I15) | K15: =COUNTIFS($A$17:$A$258,">=T31",$A$17:$A$258,"<=T60",$E$17:$E$258,"false alarm") | L15: =K15/30 | M15: =COUNTIFS($A$267:$A$766,">=T31",$A$267:$A$766,"<=T60") | N15: =COUNTIFS($A$267:$A$766,">=T31",$A$267:$A$766,"<=T60",$C$267:$C$766,"not there")
A16: transcript_id | B16: feature | C16: planted (Y/N) | D16: reported (Y/N) | E16: result (hit/miss/false alarm) | G16: All 60 | H16: =COUNTIFS($A$17:$A$258,">=T01",$A$17:$A$258,"<=T60",$E$17:$E$258,"hit") | I16: =COUNTIFS($A$17:$A$258,">=T01",$A$17:$A$258,"<=T60",$C$17:$C$258,"Y") | J16: =IF(I16=0,"",H16/I16) | K16: =COUNTIFS($A$17:$A$258,">=T01",$A$17:$A$258,"<=T60",$E$17:$E$258,"false alarm") | L16: =K16/60 | M16: =COUNTIFS($A$267:$A$766,">=T01",$A$267:$A$766,"<=T60") | N16: =COUNTIFS($A$267:$A$766,">=T01",$A$267:$A$766,"<=T60",$C$267:$C$766,"not there")
A17: T01 | B17: Leaves out: where | C17: Y | D17: Y | E17: hit
A18: T01 | B18: Uses 'because' | C18: Y | D18: Y | E18: hit
A19: T01 | B19: Emotion word: scared | C19: Y | D19: Y | E19: hit
A20: T01 | B20: Emotion word: happy | C20: Y | D20: Y | E20: hit
A21: T01 | B21: False alarm: why they felt | C21: N | D21: Y | E21: false alarm
A22: T02 | B22: Leaves out: how it ended | C22: Y | D22: Y | E22: hit
A23: T02 | B23: Uses neither 'because' nor 'so' | C23: Y | D23: Y | E23: hit
A24: T02 | B24: Emotion word: excited | C24: Y | D24: Y | E24: hit
A25: T03 | B25: Leaves out: who | C25: Y | D25: Y | E25: hit
A26: T03 | B26: Uses 'so' | C26: Y | D26: Y | E26: hit
A27: T03 | B27: Emotion word: sad | C27: Y | D27: Y | E27: hit
A28: T03 | B28: Emotion word: worried | C28: Y | D28: N | E28: miss
... A256: T60 | B256: False alarm: why they felt | C256: N | D256: Y | E256: false alarm
A265: Quotes: every example the analysis quotes as said in the session, checked against the transcript
A266: transcript_id | B266: quote | C266: found (exact/reworded/not there)
A267: T01 | B267: My dad. And Jo. Jo's the teacher. | C267: exact
A268: T01 | B268: We did jumping in. In the deep end. Jumping into the deep end. I didn't want to because it was really deep. Scared. Jo held my hand. Then I jumped. I got a sticker. | C268: exact
A269: T01 | B269: I got a sticker. Happy. | C269: exact
A270: T01 | B270: I didn't want to because it was really deep. | C270: exact
A271: T01 | B271: then | C271: exact
A272: T01 | B272: Scared. | C272: exact
A273: T01 | B273: Happy. | C273: exact
A274: T02 | B274: Lots of people. From my class. | C274: exact
A275: T02 | B275: At the soft play. | C275: exact
A276: T02 | B276: We went on the big slide. Then pizza. Hana opened presents. I gave her a unicorn. | C276: exact
...

Sheet NFR3 Version comparison
A1: NFR3 · Lesson-plan accuracy (Test 6) — Version comparison
A3: Transcript set | B3: v1 hit rate | C3: v1 false alarms per transcript | D3: v2 hit rate | E3: v2 false alarms per transcript | F3: v3 hit rate | G3: v3 false alarms per transcript
A4: T01–T10 | B4: ='NFR3 Version 1'!J12 | C4: ='NFR3 Version 1'!L12 | D4: ='NFR3 Version 2'!J12 | E4: ='NFR3 Version 2'!L12 | F4: 0.9459 | G4: 0.3
A5: T11–T20 | B5: ='NFR3 Version 1'!J13 | C5: ='NFR3 Version 1'!L13 | D5: ='NFR3 Version 2'!J13 | E5: ='NFR3 Version 2'!L13 | F5: 0.9444 | G5: 0.5
A6: T21–T30 | B6: ='NFR3 Version 1'!J14 | C6: ='NFR3 Version 1'!L14 | D6: ='NFR3 Version 2'!J14 | E6: ='NFR3 Version 2'!L14 | F6: 0.6923 | G6: 0.2
A7: T31–T60 | B7: ='NFR3 Version 1'!J15 | C7: ='NFR3 Version 1'!L15 | D7: ='NFR3 Version 2'!J15 | E7: ='NFR3 Version 2'!L15 | F7: 0.8551 | G7: 0.7
A8: All 60 | B8: ='NFR3 Version 1'!J16 | C8: ='NFR3 Version 1'!L16 | D8: ='NFR3 Version 2'!J16 | E8: ='NFR3 Version 2'!L16 | F8: 0.8564 | G8: 0.5167
A10: Notes
A11: v1 used the labelled transcripts; v2 and v3 used transcripts with the speaker labels removed and re-added automatically.
A12: T01–T10 were development transcripts for v2.
A13: v3's fixes were designed from v2's failures on T21–T60, so v3's figures on those sets are not held-out results.
A14: v1 and v2: this re-run (21 October 2026); the v1 and v2 cells are formulas on the version sheets. v3: computed from the existing sheet 'NFR3 Lesson-plan accuracy (V3)' in Evaluation_Results (Version 2).xlsx (not re-run).
A15: v2 and v3 were scored by the same automatic scorer (compare.py); v1 writes free text and was scored by reading it, with the same truth sheets and rules.
